<?xml version="1.0"?>
<robot name="aubo_i5" xmlns:xacro="http://ros.org/wiki/xacro">

 <!-- Defining the colors used in this robot -->
    <material name="Black">
        <color rgba="0 0 0 1"/>
    </material>

    <material name="White">
        <color rgba="1 1 1 1"/>
    </material>

    <material name="Blue">
        <color rgba="0 0 1 1"/>
    </material>

    <material name="Red">
        <color rgba="1 0 0 1"/>
    </material>

    <material name="Grey">
        <color rgba="0.96 0.96 0.96 1"/>
    </material>

    <!-- Constants -->
    <xacro:property name="M_PI" value="3.14159"/>
    <!--/////////////////// DYNAMICS PARAM //////////////////////-->

    <xacro:macro name="I5_Shoulder_Inertia">
        <origin xyz="0.0 0.006 -0.002"
                rpy="0 0 0" />
        <mass value="5.05" />
        <inertia ixx="0.0148"
                 ixy="0"
                 ixz="0"
                 iyy="0.0143"
                 iyz="-0.0"
                 izz="0.0095" />
    </xacro:macro>

    <xacro:macro name="I5_UpperArm_Inertia">
        <origin xyz="0.304 0.0 -0.03"
                rpy="0 0 0" />
        <mass value="11.90" />
        <inertia ixx="0.0305"
                 ixy="0"
                 ixz="0"
                 iyy="0.4505"
                 iyz="0"
                 izz="0.0095" />
    </xacro:macro>

    <xacro:macro name="I5_ForeArm_Inertia">
        <origin xyz="0.415 0.0 0.0992"
                rpy="0 0 0" />
        <mass  value="3.3" />
        <inertia ixx="0.0033"
                 ixy="0"
                 ixz="0.0009"
                 iyy="0.0575"
                 iyz="0"
                 izz="0.0565" />
    </xacro:macro>

    <xacro:macro name="I5_Wrist1_Inertia">
        <origin xyz="0.0 0.0028 -0.003"
                rpy="0 0 0" />
        <mass value="1.62" />
        <inertia ixx="0.0023"
                 ixy="0"
                 ixz="0"
                 iyy="0.0013"
                 iyz="0.0"
                 izz="0.0022" />
    </xacro:macro>

    <xacro:macro name="I5_Wrist2_Inertia">
        <origin xyz="0.0 -0.0028 -0.003"
                rpy="0 0 0" />
        <mass value="1.62" />
        <inertia ixx="0.0023"
                 ixy="0"
                 ixz="0"
                 iyy="0.0013"
                 iyz="0.0"
                 izz="0.0022" />
    </xacro:macro>

    <xacro:macro name="I5_Wrist3_Inertia">
        <origin xyz="0.0 0.0 -0.0071"
                rpy="0 0 0" />
        <mass value="0.40" />
        <inertia ixx="0.013939"
                 ixy="0"
                 ixz="0"
                 iyy="0.013988"
                 iyz="0.0"
                 izz="0.0224092" />
    </xacro:macro>

    <!--/////////////////////////////// BASE_LINK ////////////////////////////////////-->

  <!--/////////////////////////////// SHOULDER_LINK ////////////////////////////////////-->
  <link name="shoulder_Link">
    <inertial>
      <xacro:I5_Shoulder_Inertia />
    </inertial>
    <visual>
      <origin xyz="0 0 0" rpy="0 0 0" />
      <geometry>
        <mesh filename="package://aubo_description/meshes/aubo_i5/visual/shoulder_Link.DAE" />
      </geometry>
      <material name="">
        <color rgba="1 1 1 1" />
      </material>
    </visual>
    <collision>
      <origin xyz="0 0 0" rpy="0 0 0" />
      <geometry>
        <mesh filename="package://aubo_description/meshes/aubo_i5/collision/shoulder_Link.STL" />
      </geometry>
    </collision>
  </link>


  <!--/////////////////////////////// SHOULDER_JOINT ////////////////////////////// 0.243 0.14 -1.222/-->
  <joint name="shoulder_joint" type="revolute">
    <origin xyz="0.243 0.14 -1.22" rpy="0 0 0" />
    <parent link="axis_y" />
    <child link="shoulder_Link" />
    <axis xyz="0 0 1" />
    <limit lower="-3.05" upper="3.05" effort="300" velocity="100" />
  </joint>


  <!--/////////////////////////////// UPPERARM_LINK ////////////////////////////////////-->
  <link name="upperArm_Link">
    <inertial>
      <xacro:I5_UpperArm_Inertia />
    </inertial>
    <visual>
      <origin xyz="0 0 0" rpy="0 0 0" />
      <geometry>
        <mesh filename="package://aubo_description/meshes/aubo_i5/visual/upperArm_Link.DAE" />
      </geometry>
      <material name="">
        <color rgba="1 1 1 1" />
      </material>
    </visual>
    <collision>
      <origin xyz="0 0 0" rpy="0 0 0" />
      <geometry>
        <mesh filename="package://aubo_description/meshes/aubo_i5/collision/upperArm_Link.STL" />
      </geometry>
    </collision>
  </link>

  <!--/////////////////////////////// UPPERARM_JOINT ////////////////////////////////////-->
  <joint name="upperArm_joint" type="revolute">
    <origin xyz="0 0.1215 0" rpy="-1.5708 1.5708 0" />
    <parent link="shoulder_Link" />
    <child link="upperArm_Link" />
    <axis xyz="0 0 1" />
    <limit lower="-3.05" upper="3.05" effort="300" velocity="100" />
  </joint>


  <!--/////////////////////////////// FOREARM_LINK ////////////////////////////////////-->
  <link name="foreArm_Link">
    <inertial>
      <xacro:I5_ForeArm_Inertia />
    </inertial>
    <visual>
      <origin xyz="0 0 0" rpy="0 0 0" />
      <geometry>
        <mesh filename="package://aubo_description/meshes/aubo_i5/visual/foreArm_Link.DAE" />
      </geometry>
      <material name="">
        <color rgba="1 1 1 1" />
      </material>
    </visual>
    <collision>
      <origin xyz="0 0 0" rpy="0 0 0" />
      <geometry>
        <mesh filename="package://aubo_description/meshes/aubo_i5/collision/foreArm_Link.STL" />
      </geometry>
    </collision>
  </link>


  <!--/////////////////////////////// FOREARM_JOINT ////////////////////////////////////-->
  <joint name="foreArm_joint" type="revolute">
    <origin xyz="0.408 0 0" rpy="-3.1416 -5.1632E-18 -5.459E-16" />
    <parent link="upperArm_Link" />
    <child link="foreArm_Link" />
    <axis xyz="0 0 1" />
    <limit lower="-3.05" upper="3.05" effort="300" velocity="100" />
  </joint>


  <!--/////////////////////////////// WRIST1_LINK ////////////////////////////////////-->
  <link name="wrist1_Link">
    <inertial>
      <xacro:I5_Wrist1_Inertia />
    </inertial>
    <visual>
      <origin xyz="0 0 0" rpy="0 0 0" />
      <geometry>
        <mesh filename="package://aubo_description/meshes/aubo_i5/visual/wrist1_Link.DAE" />
      </geometry>
      <material name="">
        <color rgba="1 1 1 1" />
      </material>
    </visual>
    <collision>
      <origin xyz="0 0 0" rpy="0 0 0" />
      <geometry>
        <mesh filename="package://aubo_description/meshes/aubo_i5/collision/wrist1_Link.STL" />
      </geometry>
    </collision>
  </link>


  <!--/////////////////////////////// WRIST1_JOINT ////////////////////////////////////-->
  <joint name="wrist1_joint" type="revolute">
    <origin xyz="0.376 0 0" rpy="3.1416 -1.8323E-15 1.5708" />
    <parent link="foreArm_Link" />
    <child link="wrist1_Link" />
    <axis xyz="0 0 1" />
    <limit lower="-3.05" upper="3.05" effort="300" velocity="100" />
  </joint>

  <!--/////////////////////////////// WRIST2_LINK ////////////////////////////////////-->
  <link name="wrist2_Link">
    <inertial>
      <xacro:I5_Wrist2_Inertia />
    </inertial>
    <visual>
      <origin xyz="0 0 0" rpy="0 0 0" />
      <geometry>
        <mesh filename="package://aubo_description/meshes/aubo_i5/visual/wrist2_Link.DAE" />
      </geometry>
      <material name="">
        <color rgba="1 1 1 1" />
      </material>
    </visual>
    <collision>
      <origin xyz="0 0 0" rpy="0 0 0" />
      <geometry>
        <mesh filename="package://aubo_description/meshes/aubo_i5/collision/wrist2_Link.STL" />
      </geometry>
    </collision>
  </link>

  <!--/////////////////////////////// WRIST2_JOINT ////////////////////////////////////-->
  <joint name="wrist2_joint" type="revolute">
    <origin xyz="0 0.1025 0" rpy="-1.5708 -1.8709E-15 -1.6653E-16" />
    <parent link="wrist1_Link" />
    <child link="wrist2_Link" />
    <axis xyz="0 0 1" />
    <limit lower="-3.05" upper="3.05" effort="300" velocity="100" />
  </joint>

  <!--/////////////////////////////// WRIST3_LINK ////////////////////////////////////-->
  <link name="wrist3_Link">
    <inertial>
      <xacro:I5_Wrist3_Inertia />
    </inertial>
    <visual>
      <origin xyz="0 0 0" rpy="0 0 0" />
      <geometry>
        <mesh filename="package://aubo_description/meshes/aubo_i5/visual/wrist3_Link.DAE" />
      </geometry>
      <material name="">
        <color rgba="1 1 1 1" />
      </material>
    </visual>
    <collision>
      <origin xyz="0 0 0" rpy="0 0 0" />
      <geometry>
        <mesh filename="package://aubo_description/meshes/aubo_i5/collision/wrist3_Link.STL" />
      </geometry>
    </collision>
  </link>

  <!--/////////////////////////////// WRIST3_JOINT ////////////////////////////////////-->
  <joint name="wrist3_joint" type="revolute">
    <origin xyz="0 -0.094 0" rpy="1.5708 0 1.7907E-15" />
    <parent link="wrist2_Link" />
    <child link="wrist3_Link" />
    <axis xyz="0 0 1" />
    <limit lower="-3.05" upper="3.05" effort="300" velocity="100" />
  </joint>



  <link
    name="room">
    <inertial>
      <origin
        xyz="4.18825944227139 0.00311131656112593 1.41015415199359"
        rpy="0 0 0" />
      <mass
        value="719.183678876683" />
      <inertia
        ixx="758.993538389474"
        ixy="4.48123193280921E-06"
        ixz="-0.332582305836725"
        iyy="1454.98114397688"
        iyz="-1.46756667565485E-05"
        izz="1493.48674065897" />
    </inertial>
    <visual>
      <origin
        xyz="0 0 0"
        rpy="0 0 0" />
      <geometry>
        <mesh
          filename="package://aubo_description/meshes/room.STL" />
      </geometry>
      <material
        name="">
        <color
          rgba="0 0 1 1" />
      </material>
    </visual>
    <collision>
      <origin
        xyz="0 0 0"
        rpy="0 0 0" />
      <geometry>
        <mesh
          filename="package://aubo_description/meshes/room.STL" />
      </geometry>
    </collision>
  </link>
  <link
    name="axis_x">
    <inertial>
      <origin
        xyz="0.222053559719226 2.21976980005625 0.0206368753509669"
        rpy="0 0 0" />
      <mass
        value="56.2326042415849" />
      <inertia
        ixx="73.7031163614978"
        ixy="-2.18843580735883E-05"
        ixz="-5.54873479813806E-08"
        iyy="0.33486100143943"
        iyz="-0.000159124005640953"
        izz="73.9991495636087" />
    </inertial>
    <visual>
      <origin
        xyz="0 0 0"
        rpy="0 0 0" />
      <geometry>
        <mesh
          filename="package://aubo_description/meshes/collision/axis2.STL" />
      </geometry>
      <material
        name="">
        <color
          rgba="0 1 1 1" />
      </material>
    </visual>
    <collision>
      <origin
        xyz="0 0 0"
        rpy="0 0 0" />
      <geometry>
        <mesh
          filename="package://aubo_description/meshes/collision/axis2.STL" />
      </geometry>
    </collision>
  </link>
  <joint
    name="axis_x_joint"
    type="prismatic">
    <origin
      xyz="0.1 -2.2018 2.737"
      rpy="0 0 0" />
    <parent
      link="room" />
    <child
      link="axis_x" />
    <axis
      xyz="-1 0 0" />
    <limit
      lower="-5.5"
      upper="0"
      effort="100"
      velocity="100" />
  </joint>
  <link
    name="axis_y">
    <inertial>
      <origin
        xyz="0.252334066113213 0.151053199816647 -0.349428411677738"
        rpy="0 0 0" />
      <mass
        value="16.6709368659665" />
      <inertia
        ixx="0.599152753172435"
        ixy="8.8006748130009E-06"
        ixz="-1.4331541654046E-05"
        iyy="0.66107899459389"
        iyz="0.0241357654191262"
        izz="0.228076435879756" />
    </inertial>
    <visual>
      <origin
        xyz="0 0 0"
        rpy="0 0 0" />
      <geometry>
        <mesh
          filename="package://aubo_description/meshes/collision/axis3.STL" />
      </geometry>
      <material
        name="">
        <color
          rgba="1 1 0 1" />
      </material>
    </visual>
    <collision>
      <origin
        xyz="0 0 0"
        rpy="0 0 0" />
      <geometry>
        <mesh
          filename="package://aubo_description/meshes/collision/axis3.STL" />
      </geometry>
    </collision>
  </link>
  <joint
    name="axis_y_joint"
    type="prismatic">
    <origin
      xyz="-0.0305 1.05 0.137"
      rpy="0 0 0" />
    <parent
      link="axis_x" />
    <child
      link="axis_y" />
    <axis
      xyz="0 1 0" />
    <limit
      lower="-0.5"
      upper="2.7"
      effort="100"
      velocity="100" />
  </joint>



  <link name="world" />

  <joint name="world_joint" type="fixed">
    <parent link="world" />
    <child link ="room" />
    <origin xyz="0.0 0.0 0.0" rpy="0.0 0.0 0.0" />
  </joint>

  <!-- <joint name="attachment_joint" type="fixed">
      <parent link="axis_y" />
      <child link="shoulder_Link" />
      <origin xyz="0.243 0.14 -1.306" rpy="0 0.0 0" />
  </joint> -->

</robot>
