<?xml version="1.0" ?>
<!-- =================================================================================== -->
<!-- |    This document was autogenerated by xacro from aubo_i5.xacro                  | -->
<!-- |    EDITING THIS FILE BY HAND IS NOT RECOMMENDED                                 | -->
<!-- =================================================================================== -->
<robot name="aubo_i5" xmlns:xacro="http://ros.org/wiki/xacro">
  <!-- Defining the colors used in this robot -->
  <material name="Black">
    <color rgba="0 0 0 1"/>
  </material>
  <material name="White">
    <color rgba="1 1 1 1"/>
  </material>
  <material name="Blue">
    <color rgba="0 0 1 1"/>
  </material>
  <material name="Red">
    <color rgba="1 0 0 1"/>
  </material>
  <material name="Grey">
    <color rgba="0.96 0.96 0.96 1"/>
  </material>
  <!--/////////////////// DYNAMICS PARAM //////////////////////-->
  <!--/////////////////////////////// BASE_LINK ////////////////////////////////////-->
  <!--/////////////////////////////// SHOULDER_LINK ////////////////////////////////////-->



  <link name="base_Link">
    <inertial>
      <origin rpy="0 0 0" xyz="0.0 0.000 0.0"/>
      <mass value="5.05"/>
      <inertia ixx="0" ixy="0" ixz="0" iyy="0" iyz="0.0" izz="0"/>
    </inertial>
    <visual>
      <origin rpy="0 0 0" xyz="0 0 0"/>
      <geometry>
        <mesh filename="package://aubo_description/lbd_meshes/obj/00.obj"  scale="0.001 0.001 0.001"/>
      </geometry>
      <material name="">
        <color rgba="1 1 1 1"/>
      </material>
    </visual>
    <collision>
      <origin rpy="0 0 0" xyz="0 0 0"/>
      <geometry>
        <mesh filename="package://aubo_description/lbd_meshes/obj/00.obj" scale="0.001 0.001 0.001"/>
      </geometry>
    </collision>
  </link>

   <joint name="base_joint" type="fixed">
    <parent link="axis_y"/>
    <child link="base_Link"/>
    <origin rpy="1.57 0 0.0" xyz="0.06 0.035 -1"/>
  </joint>

<!--/////////////////////////////// UPPERARM_LINK ////////////////////////////////////-->
  <link name="shoulder_Link">
    <inertial>
      <origin rpy="0 0 0" xyz="0 0.0 0"/>
      <mass value="11.90"/>
      <inertia ixx="0" ixy="0" ixz="0" iyy="0" iyz="0" izz="0"/>
    </inertial>
    <visual>
      <origin rpy="0 0 0" xyz="0 0 0"/>
      <geometry>
        <mesh filename="package://aubo_description/lbd_meshes/obj/01.obj" scale="0.001 0.001 0.001"/>
      </geometry>
      <material name="">
        <color rgba="1 1 1 1"/>
      </material>
    </visual>
    <collision>
      <origin rpy="0 0 0" xyz="0 0 0"/>
      <geometry>
        <mesh filename="package://aubo_description/lbd_meshes/obj/01.obj" scale="0.001 0.001 0.001"/>
      </geometry>
    </collision>
  </link>
  <!--/////////////////////////////// UPPERARM_JOINT ////////////////////////////////////-->
  <joint name="shoulder_joint" type="revolute">
    <origin rpy="0 0 0" xyz="0 0 0 "/>
    <parent link="base_Link"/>
    <child link="shoulder_Link"/>
    <axis xyz="0 0 0"/>
    <limit effort="300" lower="-3.05" upper="3.05" velocity="100"/>
  </joint>

  <!--/////////////////////////////// FOREARM_LINK ////////////////////////////////////-->
  <link name="upperArm_Link">
    <inertial>
      <origin rpy="0 0 0" xyz="0 0.0 0"/>
      <mass value="3.3"/>
      <inertia ixx="0.0033" ixy="0" ixz="0.0009" iyy="0.0575" iyz="0" izz="0.0565"/>
    </inertial>
    <visual>
      <origin rpy="0 0 0" xyz="0 0 0"/>
      <geometry>
        <mesh filename="package://aubo_description/lbd_meshes/obj/02.obj"  scale="0.001 0.001 0.001"/>
      </geometry>
      <material name="">
        <color rgba="1 1 1 1"/>
      </material>
    </visual>
    <collision>
      <origin rpy="0 0 0" xyz="0 0 0"/>
      <geometry>
        <mesh filename="package://aubo_description/lbd_meshes/obj/02.obj"  scale="0.001 0.001 0.001"/>
      </geometry>
    </collision>
  </link>
  <!--/////////////////////////////// FOREARM_JOINT ////////////////////////////////////-->
  <joint name="upperArm_joint" type="revolute">
    <origin rpy="0 0 0" xyz="0
     0 0"/>
    <parent link="shoulder_Link"/>
    <child link="upperArm_Link"/>
    <axis xyz="0 1 0"/>
    <limit effort="300" lower="-3.05" upper="3.05" velocity="100"/>
  </joint>


  <link name="room">
    <inertial>
      <origin rpy="0 0 0" xyz="4.18825944227139 0.00311131656112593 1.41015415199359"/>
      <mass value="719.183678876683"/>
      <inertia ixx="758.993538389474" ixy="4.48123193280921E-06" ixz="-0.332582305836725" iyy="1454.98114397688" iyz="-1.46756667565485E-05" izz="1493.48674065897"/>
    </inertial>
    <visual>
      <origin rpy="0 0 0" xyz="0 0 0"/>
      <geometry>
        <mesh filename="package://aubo_description/meshes/room.STL"/>
      </geometry>
      <material name="">
        <color rgba="0 0 1 1"/>
      </material>
    </visual>
    <collision>
      <origin rpy="0 0 0" xyz="0 0 0"/>
      <geometry>
        <mesh filename="package://aubo_description/meshes/room.STL"/>
      </geometry>
    </collision>
  </link>
  <link name="axis_x">
    <inertial>
      <origin rpy="0 0 0" xyz="0.222053559719226 2.21976980005625 0.0206368753509669"/>
      <mass value="56.2326042415849"/>
      <inertia ixx="73.7031163614978" ixy="-2.18843580735883E-05" ixz="-5.54873479813806E-08" iyy="0.33486100143943" iyz="-0.000159124005640953" izz="73.9991495636087"/>
    </inertial>
    <visual>
      <origin rpy="0 0 0" xyz="0 0 0"/>
      <geometry>
        <mesh filename="package://aubo_description/meshes/collision/axis2.STL"/>
      </geometry>
      <material name="">
        <color rgba="0 1 1 1"/>
      </material>
    </visual>
    <collision>
      <origin rpy="0 0 0" xyz="0 0 0"/>
      <geometry>
        <mesh filename="package://aubo_description/meshes/collision/axis2.STL"/>
      </geometry>
    </collision>
  </link>
  <joint name="axis_x_joint" type="prismatic">
    <origin rpy="0 0 0" xyz="0.1 -2.2018 2.737"/>
    <parent link="room"/>
    <child link="axis_x"/>
    <axis xyz="-1 0 0"/>
    <limit effort="100" lower="-5.5" upper="0" velocity="100"/>
  </joint>
  <link name="axis_y">
    <inertial>
      <origin rpy="0 0 0" xyz="0.252334066113213 0.151053199816647 -0.349428411677738"/>
      <mass value="16.6709368659665"/>
      <inertia ixx="0.599152753172435" ixy="8.8006748130009E-06" ixz="-1.4331541654046E-05" iyy="0.66107899459389" iyz="0.0241357654191262" izz="0.228076435879756"/>
    </inertial>
    <visual>
      <origin rpy="0 0 0" xyz="0 0 0"/>
      <geometry>
        <mesh filename="package://aubo_description/meshes/collision/axis3.STL"/>
      </geometry>
      <material name="">
        <color rgba="1 1 0 1"/>
      </material>
    </visual>
    <collision>
      <origin rpy="0 0 0" xyz="0 0 0"/>
      <geometry>
        <mesh filename="package://aubo_description/meshes/collision/axis3.STL"/>
      </geometry>
    </collision>
  </link>
  <joint name="axis_y_joint" type="prismatic">
    <origin rpy="0 0 0" xyz="-0.0305 1.05 0.137"/>
    <parent link="axis_x"/>
    <child link="axis_y"/>
    <axis xyz="0 1 0"/>
    <limit effort="100" lower="-0.9" upper="2.8" velocity="100"/>
  </joint>

  <link name="world"/>
  <joint name="world_joint" type="fixed">
    <parent link="world"/>
    <child link="room"/>
    <origin rpy="0 0.0 0.0" xyz="0.0 0.0 0.0"/>
  </joint>


   <!-- <joint name="new_joint" type="fixed">
    <parent link="world"/>
    <child link="box"/>
    <origin rpy="3.14 1.57 0" xyz="0 0 0 "/>
  </joint> -->




</robot>
